Workbook

Sheet Start Here
B2: CommunityCRM — Volunteer Hours Tracker + Lapsed Donor Outreach
B3: Upload this file to Google Sheets: drive.google.com → New → File upload → then Open with Google Sheets
B5: Sheet | E5: What it does
B6: Start Here | E6: This sheet — overview and instructions
B7: Hours Tracker | E7: Log volunteer hours here. Scores update automatically.
B8: Engagement Scores | E8: Live scores for every contact — auto-calculated from hours + gifts.
B9: Donations | E9: Log every donation here. Feeds lapsed list and giving scores.
B10: Lapsed Outreach | E10: Auto-filtered list of donors who haven't given in 90+ days.
B11: Contacts | E11: Master contact list — add everyone here first.
B13: HOW TO USE THIS CRM — STEP BY STEP
B14: Step 1 | D14: Open the Contacts sheet. Add or review the sample contacts. For each real person, add their name, email, and type (Volunteer, Donor, or Both).
B15: Step 2 | D15: Go to Hours Tracker. Each time a volunteer completes a shift, add a new row: Contact ID, Program, Hours, Date. The Engagement Scores sheet recalculates automatically.
B16: Step 3 | D16: Go to Donations. Each time someone gives, add a row: Contact ID, Amount, Fund, Date. This feeds both the Engagement Scores and the Lapsed Outreach list.
B17: Step 4 | D17: Check Engagement Scores anytime to see who is High / Medium / Low / At-Risk. At-Risk contacts are highlighted in red. Reach out to them first.
B18: Step 5 | D18: Check Lapsed Outreach to see donors who haven't given in 90+ days. The list auto-sorts by urgency. Use the Suggested Action column to guide your outreach.
B19: Step 6 | D19: Share this file with your team: File → Share → Share with people. Each person can log their own hours or donations directly into the sheet.

Sheet Hours Tracker
A1: Volunteer Hours Tracker — Log shifts here. Engagement scores update automatically. | K1: Volunteer Summary (auto-calculated)
A2: HOW IT WORKS: Enter Contact ID + Program + Hours + Date in each row. The Engagement Score sheet recalculates automatically.
A3: V.ID | B3: First | C3: Last | D3: Total hours | E3: # Shifts | F3: Engagement pts | G3: Date | H3: Notes | I3: Verified? | K3: V.ID | L3: First | M3: Last | N3: Total hours | O3: # Shifts | P3: Eng. pts
A4: 1 | B4: 2 | C4: Andrew | D4: Ortiz | E4: Food Bank | F4: 4.7 | G4: 2025-06-24 | H4: Great session | I4: Yes | K4: 2 | L4: Andrew | M4: Ortiz | N4: =IFERROR(SUMIF(B4:B189,2,F4:F189),0) | O4: =IFERROR(COUNTIF(B4:B189,2),0) | P4: =MIN(100,18+ROUND(N4/5,0))
A5: 2 | B5: 2 | C5: Andrew | D5: Ortiz | E5: Youth Literacy | F5: 5.2 | G5: 2025-07-23 | H5: On time, very helpful | I5: Yes | K5: 3 | L5: Paul | M5: Perez | N5: =IFERROR(SUMIF(B4:B189,3,F4:F189),0) | O5: =IFERROR(COUNTIF(B4:B189,3),0) | P5: =MIN(100,84+ROUND(N5/5,0))
A6: 3 | B6: 2 | C6: Andrew | D6: Ortiz | E6: Elder Care | F6: 7.6 | G6: 2026-03-04 | H6: Completed all tasks | I6: Yes | K6: 4 | L6: Donna | M6: Garcia | N6: =IFERROR(SUMIF(B4:B189,4,F4:F189),0) | O6: =IFERROR(COUNTIF(B4:B189,4),0) | P6: =MIN(100,35+ROUND(N6/5,0))
A7: 4 | B7: 3 | C7: Paul | D7: Perez | E7: After-School Tutoring | F7: 2.9 | G7: 2025-07-04 | H7: On time, very helpful | I7: Yes | K7: 5 | L7: David | M7: Jackson | N7: =IFERROR(SUMIF(B4:B189,5,F4:F189),0) | O7: =IFERROR(COUNTIF(B4:B189,5),0) | P7: =MIN(100,63+ROUND(N7/5,0))
A8: 5 | B8: 3 | C8: Paul | D8: Perez | E8: Food Bank | F8: 6 | G8: 2025-06-29 | H8: On time, very helpful | I8: Yes | K8: 6 | L8: George | M8: Martin | N8: =IFERROR(SUMIF(B4:B189,6,F4:F189),0) | O8: =IFERROR(COUNTIF(B4:B189,6),0) | P8: =MIN(100,83+ROUND(N8/5,0))
A9: 6 | B9: 3 | C9: Paul | D9: Perez | E9: Youth Literacy | F9: 7.6 | G9: 2026-01-30 | H9: On time, very helpful | I9: Yes | K9: 8 | L9: Jessica | M9: Martinez | N9: =IFERROR(SUMIF(B4:B189,8,F4:F189),0) | O9: =IFERROR(COUNTIF(B4:B189,8),0) | P9: =MIN(100,27+ROUND(N9/5,0))
A10: 7 | B10: 3 | C10: Paul | D10: Perez | E10: Youth Literacy | F10: 7.3 | G10: 2025-06-29 | H10: Completed all tasks | I10: Yes | K10: 12 | L10: Anthony | M10: Garcia | N10: =IFERROR(SUMIF(B4:B189,12,F4:F189),0) | O10: =IFERROR(COUNTIF(B4:B189,12),0) | P10: =MIN(100,87+ROUND(N10/5,0))
A11: 8 | B11: 3 | C11: Paul | D11: Perez | E11: After-School Tutoring | F11: 3.7 | G11: 2025-12-22 | H11: On time, very helpful | I11: Yes | K11: 14 | L11: Emily | M11: Baker | N11: =IFERROR(SUMIF(B4:B189,14,F4:F189),0) | O11: =IFERROR(COUNTIF(B4:B189,14),0) | P11: =MIN(100,69+ROUND(N11/5,0))
A12: 9 | B12: 3 | C12: Paul | D12: Perez | E12: Community Garden | F12: 6.1 | G12: 2025-11-24 | I12: Yes | K12: 15 | L12: Elizabeth | M12: Green | N12: =IFERROR(SUMIF(B4:B189,15,F4:F189),0) | O12: =IFERROR(COUNTIF(B4:B189,15),0) | P12: =MIN(100,21+ROUND(N12/5,0))
A13: 10 | B13: 3 | C13: Paul | D13: Perez | E13: Environmental Cleanup | F13: 3.5 | G13: 2026-03-13 | H13: Great session | I13: Yes | K13: 16 | L13: Jennifer | M13: King | N13: =IFERROR(SUMIF(B4:B189,16,F4:F189),0) | O13: =IFERROR(COUNTIF(B4:B189,16),0) | P13: =MIN(100,63+ROUND(N13/5,0))
A14: 11 | B14: 4 | C14: Donna | D14: Garcia | E14: After-School Tutoring | F14: 2.3 | G14: 2025-10-20 | H14: Completed all tasks | I14: Yes | K14: 18 | L14: William | M14: Martinez | N14: =IFERROR(SUMIF(B4:B189,18,F4:F189),0) | O14: =IFERROR(COUNTIF(B4:B189,18),0) | P14: =MIN(100,15+ROUND(N14/5,0))
A15: 12 | B15: 4 | C15: Donna | D15: Garcia | E15: After-School Tutoring | F15: 3 | G15: 2025-08-25 | I15: Yes | K15: 19 | L15: Richard | M15: Green | N15: =IFERROR(SUMIF(B4:B189,19,F4:F189),0) | O15: =IFERROR(COUNTIF(B4:B189,19),0) | P15: =MIN(100,9+ROUND(N15/5,0))
A16: 13 | B16: 4 | C16: Donna | D16: Garcia | E16: Job Training | F16: 5.4 | G16: 2026-02-10 | H16: Great session | I16: Yes | K16: 20 | L16: Jennifer | M16: Baker | N16: =IFERROR(SUMIF(B4:B189,20,F4:F189),0) | O16: =IFERROR(COUNTIF(B4:B189,20),0) | P16: =MIN(100,19+ROUND(N16/5,0))
A17: 14 | B17: 4 | C17: Donna | D17: Garcia | E17: Elder Care | F17: 5.3 | G17: 2025-10-01 | I17: Yes | K17: 21 | L17: William | M17: Walker | N17: =IFERROR(SUMIF(B4:B189,21,F4:F189),0) | O17: =IFERROR(COUNTIF(B4:B189,21),0) | P17: =MIN(100,45+ROUND(N17/5,0))
A18: 15 | B18: 4 | C18: Donna | D18: Garcia | E18: Elder Care | F18: 4.6 | G18: 2026-03-18 | H18: On time, very helpful | I18: Yes | K18: 22 | L18: Dorothy | M18: Chen | N18: =IFERROR(SUMIF(B4:B189,22,F4:F189),0) | O18: =IFERROR(COUNTIF(B4:B189,22),0) | P18: =MIN(100,31+ROUND(N18/5,0))
A19: 16 | B19: 4 | C19: Donna | D19: Garcia | E19: Mental Health Support | F19: 7.4 | G19: 2026-03-19 | H19: On time, very helpful | I19: Yes | K19: 23 | L19: Sarah | M19: Adams | N19: =IFERROR(SUMIF(B4:B189,23,F4:F189),0) | O19: =IFERROR(COUNTIF(B4:B189,23),0) | P19: =MIN(100,42+ROUND(N19/5,0))
A20: 17 | B20: 4 | C20: Donna | D20: Garcia | E20: Community Garden | F20: 6.1 | G20: 2025-05-02 | H20: Great session | I20: Yes | K20: 24 | L20: Matthew | M20: Wright | N20: =IFERROR(SUMIF(B4:B189,24,F4:F189),0) | O20: =IFERROR(COUNTIF(B4:B189,24),0) | P20: =MIN(100,46+ROUND(N20/5,0))
A21: 18 | B21: 4 | C21: Donna | D21: Garcia | E21: Mental Health Support | F21: 6.7 | G21: 2025-09-12 | I21: Yes | K21: 25 | L21: James | M21: Mitchell | N21: =IFERROR(SUMIF(B4:B189,25,F4:F189),0) | O21: =IFERROR(COUNTIF(B4:B189,25),0) | P21: =MIN(100,43+ROUND(N21/5,0))
A22: 19 | B22: 5 | C22: David | D22: Jackson | E22: Community Garden | F22: 7.2 | G22: 2026-01-08 | H22: Ran extra 30 min | I22: Yes | K22: 26 | L22: Robert | M22: White | N22: =IFERROR(SUMIF(B4:B189,26,F4:F189),0) | O22: =IFERROR(COUNTIF(B4:B189,26),0) | P22: =MIN(100,27+ROUND(N22/5,0))
A23: 20 | B23: 5 | C23: David | D23: Jackson | E23: Food Bank | F23: 3.1 | G23: 2025-10-20 | H23: Ran extra 30 min | I23: Yes | K23: 28 | L23: Steven | M23: Harris | N23: =IFERROR(SUMIF(B4:B189,28,F4:F189),0) | O23: =IFERROR(COUNTIF(B4:B189,28),0) | P23: =MIN(100,39+ROUND(N23/5,0))
A24: 21 | B24: 5 | C24: David | D24: Jackson | E24: Community Garden | F24: 3.6 | G24: 2025-04-14 | H24: Great session | I24: Yes | K24: 29 | L24: Sandra | M24: Lewis | N24: =IFERROR(SUMIF(B4:B189,29,F4:F189),0) | O24: =IFERROR(COUNTIF(B4:B189,29),0) | P24: =MIN(100,21+ROUND(N24/5,0))
A25: 22 | B25: 5 | C25: David | D25: Jackson | E25: Job Training | F25: 7.2 | G25: 2025-08-11 | H25: Completed all tasks | I25: Yes | K25: 31 | L25: Richard | M25: Garcia | N25: =IFERROR(SUMIF(B4:B189,31,F4:F189),0) | O25: =IFERROR(COUNTIF(B4:B189,31),0) | P25: =MIN(100,24+ROUND(N25/5,0))
A26: 23 | B26: 6 | C26: George | D26: Martin | E26: Environmental Cleanup | F26: 4.1 | G26: 2025-12-13 | H26: Completed all tasks | I26: Yes | K26: 32 | L26: Robert | M26: Baker | N26: =IFERROR(SUMIF(B4:B189,32,F4:F189),0) | O26: =IFERROR(COUNTIF(B4:B189,32),0) | P26: =MIN(100,29+ROUND(N26/5,0))
A27: 24 | B27: 6 | C27: George | D27: Martin | E27: Food Bank | F27: 6 | G27: 2025-09-16 | H27: On time, very helpful | I27: Yes | K27: 34 | L27: Maria | M27: Hall | N27: =IFERROR(SUMIF(B4:B189,34,F4:F189),0) | O27: =IFERROR(COUNTIF(B4:B189,34),0) | P27: =MIN(100,25+ROUND(N27/5,0))
A28: 25 | B28: 6 | C28: George | D28: Martin | E28: After-School Tutoring | F28: 7.2 | G28: 2025-11-17 | H28: On time, very helpful | I28: Yes | K28: 37 | L28: Jennifer | M28: Kim | N28: =IFERROR(SUMIF(B4:B189,37,F4:F189),0) | O28: =IFERROR(COUNTIF(B4:B189,37),0) | P28: =MIN(100,38+ROUND(N28/5,0))
A29: 26 | B29: 6 | C29: George | D29: Martin | E29: Job Training | F29: 6.1 | G29: 2025-07-08 | H29: On time, very helpful | I29: Yes | K29: 38 | L29: Thomas | M29: Allen | N29: =IFERROR(SUMIF(B4:B189,38,F4:F189),0) | O29: =IFERROR(COUNTIF(B4:B189,38),0) | P29: =MIN(100,18+ROUND(N29/5,0))
A30: 27 | B30: 6 | C30: George | D30: Martin | E30: Food Bank | F30: 2.7 | G30: 2025-11-26 | H30: Completed all tasks | I30: Yes | K30: 39 | L30: Patricia | M30: Roberts | N30: =IFERROR(SUMIF(B4:B189,39,F4:F189),0) | O30: =IFERROR(COUNTIF(B4:B189,39),0) | P30: =MIN(100,89+ROUND(N30/5,0))
A31: 28 | B31: 8 | C31: Jessica | D31: Martinez | E31: Food Bank | F31: 2.7 | G31: 2025-08-29 | H31: On time, very helpful | I31: Yes | K31: 40 | L31: Lisa | M31: Harris | N31: =IFERROR(SUMIF(B4:B189,40,F4:F189),0) | O31: =IFERROR(COUNTIF(B4:B189,40),0) | P31: =MIN(100,53+ROUND(N31/5,0))
A32: 29 | B32: 8 | C32: Jessica | D32: Martinez | E32: Mental Health Support | F32: 4.6 | G32: 2025-07-21 | H32: Great session | I32: Yes
A33: 30 | B33: 8 | C33: Jessica | D33: Martinez | E33: Job Training | F33: 7.4 | G33: 2026-01-01 | H33: On time, very helpful | I33: Yes
A34: 31 | B34: 8 | C34: Jessica | D34: Martinez | E34: Food Bank | F34: 6.3 | G34: 2026-04-08 | I34: Yes
A35: 32 | B35: 8 | C35: Jessica | D35: Martinez | E35: Community Garden | F35: 4.2 | G35: 2026-03-04 | H35: On time, very helpful | I35: Yes
A36: 33 | B36: 8 | C36: Jessica | D36: Martinez | E36: Mental Health Support | F36: 6 | G36: 2026-02-04 | H36: On time, very helpful | I36: Yes
A37: 34 | B37: 12 | C37: Anthony | D37: Garcia | E37: After-School Tutoring | F37: 6 | G37: 2025-10-23 | H37: Ran extra 30 min | I37: Yes
A38: 35 | B38: 12 | C38: Anthony | D38: Garcia | E38: After-School Tutoring | F38: 5.3 | G38: 2025-12-31 | H38: Ran extra 30 min | I38: Yes
A39: 36 | B39: 12 | C39: Anthony | D39: Garcia | E39: Job Training | F39: 6.1 | G39: 2026-01-09 | I39: Yes
A40: 37 | B40: 12 | C40: Anthony | D40: Garcia | E40: After-School Tutoring | F40: 4.4 | G40: 2026-04-08 | H40: On time, very helpful | I40: Yes
...

Sheet Engagement Scores
A1: Engagement Scores — Automatically calculated from hours, donations & activity
A2: Scores update live. Green = High (70+) · Blue = Medium (40–69) · Amber = Low (20–39) · Red = At-Risk (<20)
A3: Contact ID | B3: First | C3: Last | D3: Type | E3: Base score | F3: Hours pts | G3: Giving pts | H3: Total score | I3: Tier | J3: Last activity | K3: Email
A4: 1 | B4: William | C4: Thornton | D4: Donor | E4: 43 | F4: =IFERROR(ROUND(SUMIF('Hours Tracker'!B4:B2000,1,'Hours Tracker'!F4:F2000)/5,0),0) | G4: =IFERROR(MIN(30,ROUND(SUMIF(Donations!B4:B2000,1,Donations!E4:E2000)/50,0)),0) | H4: =MIN(100,E4+F4+G4) | I4: =IF(H4>=70,"High",IF(H4>=40,"Medium",IF(H4>=20,"Low","At-Risk"))) | J4: 2025-10-17 | K4: william.thornton1@example.com
A5: 2 | B5: Andrew | C5: Ortiz | D5: Volunteer | E5: 18 | F5: =IFERROR(ROUND(SUMIF('Hours Tracker'!B4:B2000,2,'Hours Tracker'!F4:F2000)/5,0),0) | G5: =IFERROR(MIN(30,ROUND(SUMIF(Donations!B4:B2000,2,Donations!E4:E2000)/50,0)),0) | H5: =MIN(100,E5+F5+G5) | I5: =IF(H5>=70,"High",IF(H5>=40,"Medium",IF(H5>=20,"Low","At-Risk"))) | J5: 2026-02-08 | K5: andrew.ortiz2@example.com
A6: 3 | B6: Paul | C6: Perez | D6: Volunteer | E6: 84 | F6: =IFERROR(ROUND(SUMIF('Hours Tracker'!B4:B2000,3,'Hours Tracker'!F4:F2000)/5,0),0) | G6: =IFERROR(MIN(30,ROUND(SUMIF(Donations!B4:B2000,3,Donations!E4:E2000)/50,0)),0) | H6: =MIN(100,E6+F6+G6) | I6: =IF(H6>=70,"High",IF(H6>=40,"Medium",IF(H6>=20,"Low","At-Risk"))) | J6: 2025-12-15 | K6: paul.perez3@example.com
A7: 4 | B7: Donna | C7: Garcia | D7: Volunteer | E7: 35 | F7: =IFERROR(ROUND(SUMIF('Hours Tracker'!B4:B2000,4,'Hours Tracker'!F4:F2000)/5,0),0) | G7: =IFERROR(MIN(30,ROUND(SUMIF(Donations!B4:B2000,4,Donations!E4:E2000)/50,0)),0) | H7: =MIN(100,E7+F7+G7) | I7: =IF(H7>=70,"High",IF(H7>=40,"Medium",IF(H7>=20,"Low","At-Risk"))) | J7: 2026-01-27 | K7: donna.garcia4@example.com
A8: 5 | B8: David | C8: Jackson | D8: Both | E8: 63 | F8: =IFERROR(ROUND(SUMIF('Hours Tracker'!B4:B2000,5,'Hours Tracker'!F4:F2000)/5,0),0) | G8: =IFERROR(MIN(30,ROUND(SUMIF(Donations!B4:B2000,5,Donations!E4:E2000)/50,0)),0) | H8: =MIN(100,E8+F8+G8) | I8: =IF(H8>=70,"High",IF(H8>=40,"Medium",IF(H8>=20,"Low","At-Risk"))) | J8: 2026-01-10 | K8: david.jackson5@example.com
A9: 6 | B9: George | C9: Martin | D9: Volunteer | E9: 83 | F9: =IFERROR(ROUND(SUMIF('Hours Tracker'!B4:B2000,6,'Hours Tracker'!F4:F2000)/5,0),0) | G9: =IFERROR(MIN(30,ROUND(SUMIF(Donations!B4:B2000,6,Donations!E4:E2000)/50,0)),0) | H9: =MIN(100,E9+F9+G9) | I9: =IF(H9>=70,"High",IF(H9>=40,"Medium",IF(H9>=20,"Low","At-Risk"))) | J9: 2026-03-19 | K9: george.martin6@example.com
A10: 7 | B10: Emily | C10: Martinez | D10: Donor | E10: 61 | F10: =IFERROR(ROUND(SUMIF('Hours Tracker'!B4:B2000,7,'Hours Tracker'!F4:F2000)/5,0),0) | G10: =IFERROR(MIN(30,ROUND(SUMIF(Donations!B4:B2000,7,Donations!E4:E2000)/50,0)),0) | H10: =MIN(100,E10+F10+G10) | I10: =IF(H10>=70,"High",IF(H10>=40,"Medium",IF(H10>=20,"Low","At-Risk"))) | J10: 2026-03-28 | K10: emily.martinez7@example.com
A11: 8 | B11: Jessica | C11: Martinez | D11: Volunteer | E11: 27 | F11: =IFERROR(ROUND(SUMIF('Hours Tracker'!B4:B2000,8,'Hours Tracker'!F4:F2000)/5,0),0) | G11: =IFERROR(MIN(30,ROUND(SUMIF(Donations!B4:B2000,8,Donations!E4:E2000)/50,0)),0) | H11: =MIN(100,E11+F11+G11) | I11: =IF(H11>=70,"High",IF(H11>=40,"Medium",IF(H11>=20,"Low","At-Risk"))) | J11: 2026-01-27 | K11: jessica.martinez8@example.com
A12: 9 | B12: Ashley | C12: Walker | D12: Donor | E12: 41 | F12: =IFERROR(ROUND(SUMIF('Hours Tracker'!B4:B2000,9,'Hours Tracker'!F4:F2000)/5,0),0) | G12: =IFERROR(MIN(30,ROUND(SUMIF(Donations!B4:B2000,9,Donations!E4:E2000)/50,0)),0) | H12: =MIN(100,E12+F12+G12) | I12: =IF(H12>=70,"High",IF(H12>=40,"Medium",IF(H12>=20,"Low","At-Risk"))) | J12: 2025-10-25 | K12: ashley.walker9@example.com
A13: 10 | B13: Linda | C13: Perez | D13: Donor | E13: 46 | F13: =IFERROR(ROUND(SUMIF('Hours Tracker'!B4:B2000,10,'Hours Tracker'!F4:F2000)/5,0),0) | G13: =IFERROR(MIN(30,ROUND(SUMIF(Donations!B4:B2000,10,Donations!E4:E2000)/50,0)),0) | H13: =MIN(100,E13+F13+G13) | I13: =IF(H13>=70,"High",IF(H13>=40,"Medium",IF(H13>=20,"Low","At-Risk"))) | J13: 2026-01-01 | K13: linda.perez10@example.com
A14: 11 | B14: Charles | C14: Nelson | D14: Donor | E14: 22 | F14: =IFERROR(ROUND(SUMIF('Hours Tracker'!B4:B2000,11,'Hours Tracker'!F4:F2000)/5,0),0) | G14: =IFERROR(MIN(30,ROUND(SUMIF(Donations!B4:B2000,11,Donations!E4:E2000)/50,0)),0) | H14: =MIN(100,E14+F14+G14) | I14: =IF(H14>=70,"High",IF(H14>=40,"Medium",IF(H14>=20,"Low","At-Risk"))) | J14: 2026-01-18 | K14: charles.nelson11@example.com
A15: 12 | B15: Anthony | C15: Garcia | D15: Volunteer | E15: 87 | F15: =IFERROR(ROUND(SUMIF('Hours Tracker'!B4:B2000,12,'Hours Tracker'!F4:F2000)/5,0),0) | G15: =IFERROR(MIN(30,ROUND(SUMIF(Donations!B4:B2000,12,Donations!E4:E2000)/50,0)),0) | H15: =MIN(100,E15+F15+G15) | I15: =IF(H15>=70,"High",IF(H15>=40,"Medium",IF(H15>=20,"Low","At-Risk"))) | J15: 2025-10-23 | K15: anthony.garcia12@example.com
A16: 13 | B16: Dorothy | C16: Allen | D16: Donor | E16: 48 | F16: =IFERROR(ROUND(SUMIF('Hours Tracker'!B4:B2000,13,'Hours Tracker'!F4:F2000)/5,0),0) | G16: =IFERROR(MIN(30,ROUND(SUMIF(Donations!B4:B2000,13,Donations!E4:E2000)/50,0)),0) | H16: =MIN(100,E16+F16+G16) | I16: =IF(H16>=70,"High",IF(H16>=40,"Medium",IF(H16>=20,"Low","At-Risk"))) | J16: 2025-09-30 | K16: dorothy.allen13@example.com
A17: 14 | B17: Emily | C17: Baker | D17: Both | E17: 69 | F17: =IFERROR(ROUND(SUMIF('Hours Tracker'!B4:B2000,14,'Hours Tracker'!F4:F2000)/5,0),0) | G17: =IFERROR(MIN(30,ROUND(SUMIF(Donations!B4:B2000,14,Donations!E4:E2000)/50,0)),0) | H17: =MIN(100,E17+F17+G17) | I17: =IF(H17>=70,"High",IF(H17>=40,"Medium",IF(H17>=20,"Low","At-Risk"))) | J17: 2026-02-11 | K17: emily.baker14@example.com
A18: 15 | B18: Elizabeth | C18: Green | D18: Both | E18: 21 | F18: =IFERROR(ROUND(SUMIF('Hours Tracker'!B4:B2000,15,'Hours Tracker'!F4:F2000)/5,0),0) | G18: =IFERROR(MIN(30,ROUND(SUMIF(Donations!B4:B2000,15,Donations!E4:E2000)/50,0)),0) | H18: =MIN(100,E18+F18+G18) | I18: =IF(H18>=70,"High",IF(H18>=40,"Medium",IF(H18>=20,"Low","At-Risk"))) | J18: 2025-10-30 | K18: elizabeth.green15@example.com
A19: 16 | B19: Jennifer | C19: King | D19: Volunteer | E19: 63 | F19: =IFERROR(ROUND(SUMIF('Hours Tracker'!B4:B2000,16,'Hours Tracker'!F4:F2000)/5,0),0) | G19: =IFERROR(MIN(30,ROUND(SUMIF(Donations!B4:B2000,16,Donations!E4:E2000)/50,0)),0) | H19: =MIN(100,E19+F19+G19) | I19: =IF(H19>=70,"High",IF(H19>=40,"Medium",IF(H19>=20,"Low","At-Risk"))) | J19: 2026-02-03 | K19: jennifer.king16@example.com
A20: 17 | B20: Emily | C20: Santos | D20: Donor | E20: 83 | F20: =IFERROR(ROUND(SUMIF('Hours Tracker'!B4:B2000,17,'Hours Tracker'!F4:F2000)/5,0),0) | G20: =IFERROR(MIN(30,ROUND(SUMIF(Donations!B4:B2000,17,Donations!E4:E2000)/50,0)),0) | H20: =MIN(100,E20+F20+G20) | I20: =IF(H20>=70,"High",IF(H20>=40,"Medium",IF(H20>=20,"Low","At-Risk"))) | J20: 2026-01-11 | K20: emily.santos17@example.com
A21: 18 | B21: William | C21: Martinez | D21: Both | E21: 15 | F21: =IFERROR(ROUND(SUMIF('Hours Tracker'!B4:B2000,18,'Hours Tracker'!F4:F2000)/5,0),0) | G21: =IFERROR(MIN(30,ROUND(SUMIF(Donations!B4:B2000,18,Donations!E4:E2000)/50,0)),0) | H21: =MIN(100,E21+F21+G21) | I21: =IF(H21>=70,"High",IF(H21>=40,"Medium",IF(H21>=20,"Low","At-Risk"))) | J21: 2025-09-25 | K21: william.martinez18@example.com
A22: 19 | B22: Richard | C22: Green | D22: Volunteer | E22: 9 | F22: =IFERROR(ROUND(SUMIF('Hours Tracker'!B4:B2000,19,'Hours Tracker'!F4:F2000)/5,0),0) | G22: =IFERROR(MIN(30,ROUND(SUMIF(Donations!B4:B2000,19,Donations!E4:E2000)/50,0)),0) | H22: =MIN(100,E22+F22+G22) | I22: =IF(H22>=70,"High",IF(H22>=40,"Medium",IF(H22>=20,"Low","At-Risk"))) | J22: 2026-01-03 | K22: richard.green19@example.com
A23: 20 | B23: Jennifer | C23: Baker | D23: Volunteer | E23: 19 | F23: =IFERROR(ROUND(SUMIF('Hours Tracker'!B4:B2000,20,'Hours Tracker'!F4:F2000)/5,0),0) | G23: =IFERROR(MIN(30,ROUND(SUMIF(Donations!B4:B2000,20,Donations!E4:E2000)/50,0)),0) | H23: =MIN(100,E23+F23+G23) | I23: =IF(H23>=70,"High",IF(H23>=40,"Medium",IF(H23>=20,"Low","At-Risk"))) | J23: 2026-04-04 | K23: jennifer.baker20@example.com
A24: 21 | B24: William | C24: Walker | D24: Both | E24: 45 | F24: =IFERROR(ROUND(SUMIF('Hours Tracker'!B4:B2000,21,'Hours Tracker'!F4:F2000)/5,0),0) | G24: =IFERROR(MIN(30,ROUND(SUMIF(Donations!B4:B2000,21,Donations!E4:E2000)/50,0)),0) | H24: =MIN(100,E24+F24+G24) | I24: =IF(H24>=70,"High",IF(H24>=40,"Medium",IF(H24>=20,"Low","At-Risk"))) | J24: 2025-10-03 | K24: william.walker21@example.com
A25: 22 | B25: Dorothy | C25: Chen | D25: Volunteer | E25: 31 | F25: =IFERROR(ROUND(SUMIF('Hours Tracker'!B4:B2000,22,'Hours Tracker'!F4:F2000)/5,0),0) | G25: =IFERROR(MIN(30,ROUND(SUMIF(Donations!B4:B2000,22,Donations!E4:E2000)/50,0)),0) | H25: =MIN(100,E25+F25+G25) | I25: =IF(H25>=70,"High",IF(H25>=40,"Medium",IF(H25>=20,"Low","At-Risk"))) | J25: 2026-02-25 | K25: dorothy.chen22@example.com
A26: 23 | B26: Sarah | C26: Adams | D26: Volunteer | E26: 42 | F26: =IFERROR(ROUND(SUMIF('Hours Tracker'!B4:B2000,23,'Hours Tracker'!F4:F2000)/5,0),0) | G26: =IFERROR(MIN(30,ROUND(SUMIF(Donations!B4:B2000,23,Donations!E4:E2000)/50,0)),0) | H26: =MIN(100,E26+F26+G26) | I26: =IF(H26>=70,"High",IF(H26>=40,"Medium",IF(H26>=20,"Low","At-Risk"))) | J26: 2025-12-27 | K26: sarah.adams23@example.com
A27: 24 | B27: Matthew | C27: Wright | D27: Volunteer | E27: 46 | F27: =IFERROR(ROUND(SUMIF('Hours Tracker'!B4:B2000,24,'Hours Tracker'!F4:F2000)/5,0),0) | G27: =IFERROR(MIN(30,ROUND(SUMIF(Donations!B4:B2000,24,Donations!E4:E2000)/50,0)),0) | H27: =MIN(100,E27+F27+G27) | I27: =IF(H27>=70,"High",IF(H27>=40,"Medium",IF(H27>=20,"Low","At-Risk"))) | J27: 2026-01-12 | K27: matthew.wright24@example.com
A28: 25 | B28: James | C28: Mitchell | D28: Volunteer | E28: 43 | F28: =IFERROR(ROUND(SUMIF('Hours Tracker'!B4:B2000,25,'Hours Tracker'!F4:F2000)/5,0),0) | G28: =IFERROR(MIN(30,ROUND(SUMIF(Donations!B4:B2000,25,Donations!E4:E2000)/50,0)),0) | H28: =MIN(100,E28+F28+G28) | I28: =IF(H28>=70,"High",IF(H28>=40,"Medium",IF(H28>=20,"Low","At-Risk"))) | J28: 2025-10-09 | K28: james.mitchell25@example.com
A29: 26 | B29: Robert | C29: White | D29: Volunteer | E29: 27 | F29: =IFERROR(ROUND(SUMIF('Hours Tracker'!B4:B2000,26,'Hours Tracker'!F4:F2000)/5,0),0) | G29: =IFERROR(MIN(30,ROUND(SUMIF(Donations!B4:B2000,26,Donations!E4:E2000)/50,0)),0) | H29: =MIN(100,E29+F29+G29) | I29: =IF(H29>=70,"High",IF(H29>=40,"Medium",IF(H29>=20,"Low","At-Risk"))) | J29: 2025-11-28 | K29: robert.white26@example.com
A30: 27 | B30: Thomas | C30: Garcia | D30: Donor | E30: 84 | F30: =IFERROR(ROUND(SUMIF('Hours Tracker'!B4:B2000,27,'Hours Tracker'!F4:F2000)/5,0),0) | G30: =IFERROR(MIN(30,ROUND(SUMIF(Donations!B4:B2000,27,Donations!E4:E2000)/50,0)),0) | H30: =MIN(100,E30+F30+G30) | I30: =IF(H30>=70,"High",IF(H30>=40,"Medium",IF(H30>=20,"Low","At-Risk"))) | J30: 2025-11-12 | K30: thomas.garcia27@example.com
A31: 28 | B31: Steven | C31: Harris | D31: Both | E31: 39 | F31: =IFERROR(ROUND(SUMIF('Hours Tracker'!B4:B2000,28,'Hours Tracker'!F4:F2000)/5,0),0) | G31: =IFERROR(MIN(30,ROUND(SUMIF(Donations!B4:B2000,28,Donations!E4:E2000)/50,0)),0) | H31: =MIN(100,E31+F31+G31) | I31: =IF(H31>=70,"High",IF(H31>=40,"Medium",IF(H31>=20,"Low","At-Risk"))) | J31: 2025-10-22 | K31: steven.harris28@example.com
A32: 29 | B32: Sandra | C32: Lewis | D32: Both | E32: 21 | F32: =IFERROR(ROUND(SUMIF('Hours Tracker'!B4:B2000,29,'Hours Tracker'!F4:F2000)/5,0),0) | G32: =IFERROR(MIN(30,ROUND(SUMIF(Donations!B4:B2000,29,Donations!E4:E2000)/50,0)),0) | H32: =MIN(100,E32+F32+G32) | I32: =IF(H32>=70,"High",IF(H32>=40,"Medium",IF(H32>=20,"Low","At-Risk"))) | J32: 2025-12-26 | K32: sandra.lewis29@example.com
A33: 30 | B33: Daniel | C33: Nguyen | D33: Donor | E33: 83 | F33: =IFERROR(ROUND(SUMIF('Hours Tracker'!B4:B2000,30,'Hours Tracker'!F4:F2000)/5,0),0) | G33: =IFERROR(MIN(30,ROUND(SUMIF(Donations!B4:B2000,30,Donations!E4:E2000)/50,0)),0) | H33: =MIN(100,E33+F33+G33) | I33: =IF(H33>=70,"High",IF(H33>=40,"Medium",IF(H33>=20,"Low","At-Risk"))) | J33: 2025-12-21 | K33: daniel.nguyen30@example.com
A34: 31 | B34: Richard | C34: Garcia | D34: Both | E34: 24 | F34: =IFERROR(ROUND(SUMIF('Hours Tracker'!B4:B2000,31,'Hours Tracker'!F4:F2000)/5,0),0) | G34: =IFERROR(MIN(30,ROUND(SUMIF(Donations!B4:B2000,31,Donations!E4:E2000)/50,0)),0) | H34: =MIN(100,E34+F34+G34) | I34: =IF(H34>=70,"High",IF(H34>=40,"Medium",IF(H34>=20,"Low","At-Risk"))) | J34: 2026-03-14 | K34: richard.garcia31@example.com
A35: 32 | B35: Robert | C35: Baker | D35: Volunteer | E35: 29 | F35: =IFERROR(ROUND(SUMIF('Hours Tracker'!B4:B2000,32,'Hours Tracker'!F4:F2000)/5,0),0) | G35: =IFERROR(MIN(30,ROUND(SUMIF(Donations!B4:B2000,32,Donations!E4:E2000)/50,0)),0) | H35: =MIN(100,E35+F35+G35) | I35: =IF(H35>=70,"High",IF(H35>=40,"Medium",IF(H35>=20,"Low","At-Risk"))) | J35: 2025-12-25 | K35: robert.baker32@example.com
A36: 33 | B36: Dorothy | C36: Hill | D36: Donor | E36: 28 | F36: =IFERROR(ROUND(SUMIF('Hours Tracker'!B4:B2000,33,'Hours Tracker'!F4:F2000)/5,0),0) | G36: =IFERROR(MIN(30,ROUND(SUMIF(Donations!B4:B2000,33,Donations!E4:E2000)/50,0)),0) | H36: =MIN(100,E36+F36+G36) | I36: =IF(H36>=70,"High",IF(H36>=40,"Medium",IF(H36>=20,"Low","At-Risk"))) | J36: 2026-01-01 | K36: dorothy.hill33@example.com
A37: 34 | B37: Maria | C37: Hall | D37: Both | E37: 25 | F37: =IFERROR(ROUND(SUMIF('Hours Tracker'!B4:B2000,34,'Hours Tracker'!F4:F2000)/5,0),0) | G37: =IFERROR(MIN(30,ROUND(SUMIF(Donations!B4:B2000,34,Donations!E4:E2000)/50,0)),0) | H37: =MIN(100,E37+F37+G37) | I37: =IF(H37>=70,"High",IF(H37>=40,"Medium",IF(H37>=20,"Low","At-Risk"))) | J37: 2025-12-21 | K37: maria.hall34@example.com
A38: 35 | B38: Emily | C38: Scott | D38: Donor | E38: 42 | F38: =IFERROR(ROUND(SUMIF('Hours Tracker'!B4:B2000,35,'Hours Tracker'!F4:F2000)/5,0),0) | G38: =IFERROR(MIN(30,ROUND(SUMIF(Donations!B4:B2000,35,Donations!E4:E2000)/50,0)),0) | H38: =MIN(100,E38+F38+G38) | I38: =IF(H38>=70,"High",IF(H38>=40,"Medium",IF(H38>=20,"Low","At-Risk"))) | J38: 2025-10-02 | K38: emily.scott35@example.com
A39: 36 | B39: Andrew | C39: Kim | D39: Donor | E39: 21 | F39: =IFERROR(ROUND(SUMIF('Hours Tracker'!B4:B2000,36,'Hours Tracker'!F4:F2000)/5,0),0) | G39: =IFERROR(MIN(30,ROUND(SUMIF(Donations!B4:B2000,36,Donations!E4:E2000)/50,0)),0) | H39: =MIN(100,E39+F39+G39) | I39: =IF(H39>=70,"High",IF(H39>=40,"Medium",IF(H39>=20,"Low","At-Risk"))) | J39: 2025-11-24 | K39: andrew.kim36@example.com
A40: 37 | B40: Jennifer | C40: Kim | D40: Volunteer | E40: 38 | F40: =IFERROR(ROUND(SUMIF('Hours Tracker'!B4:B2000,37,'Hours Tracker'!F4:F2000)/5,0),0) | G40: =IFERROR(MIN(30,ROUND(SUMIF(Donations!B4:B2000,37,Donations!E4:E2000)/50,0)),0) | H40: =MIN(100,E40+F40+G40) | I40: =IF(H40>=70,"High",IF(H40>=40,"Medium",IF(H40>=20,"Low","At-Risk"))) | J40: 2026-03-22 | K40: jennifer.kim37@example.com
...

Sheet Donations
A1: Donations — Every gift logged here feeds engagement scores automatically
A2: Donation ID | B2: Contact ID | C2: First name | D2: Last name | E2: Email | F2: Amount | G2: Fund | H2: Method | I2: Campaign | J2: Date | K2: Acknowledged?
A3: 1 | B3: 1 | C3: William | D3: Thornton | E3: william.thornton1@example.com | F3: 129.63 | G3: Food Bank | H3: Check | I3: Year-End Appeal | J3: 2025-11-21 | K3: Yes
A4: 2 | B4: 1 | C4: William | D4: Thornton | E4: william.thornton1@example.com | F4: 161.98 | G4: Food Bank | H4: Online | I4: GivingTuesday | J4: 2025-04-27 | K4: Yes
A5: 3 | B5: 5 | C5: David | D5: Jackson | E5: david.jackson5@example.com | F5: 89.51 | G5: Emergency Relief | H5: Credit card | I5: Spring Drive | J5: 2026-03-03 | K5: Yes
A6: 4 | B6: 7 | C6: Emily | D6: Martinez | E6: emily.martinez7@example.com | F6: 130.49 | G6: Emergency Relief | H6: Credit card | I6: Year-End Appeal | J6: 2026-04-05 | K6: Yes
A7: 5 | B7: 7 | C7: Emily | D7: Martinez | E7: emily.martinez7@example.com | F7: 433.41 | G7: Food Bank | H7: Online | I7: Fall Campaign | J7: 2025-03-05 | K7: Yes
A8: 6 | B8: 7 | C8: Emily | D8: Martinez | E8: emily.martinez7@example.com | F8: 35.73 | G8: Endowment | H8: Credit card | J8: 2025-05-02 | K8: Yes
A9: 7 | B9: 7 | C9: Emily | D9: Martinez | E9: emily.martinez7@example.com | F9: 594.83 | G9: Emergency Relief | H9: Credit card | I9: GivingTuesday | J9: 2025-09-07 | K9: Yes
A10: 8 | B10: 9 | C10: Ashley | D10: Walker | E10: ashley.walker9@example.com | F10: 47.98 | G10: Food Bank | H10: Cash | I10: Spring Drive | J10: 2026-03-04 | K10: Yes
A11: 9 | B11: 10 | C11: Linda | D11: Perez | E11: linda.perez10@example.com | F11: 351.75 | G11: Emergency Relief | H11: Credit card | J11: 2026-02-07 | K11: Yes
A12: 10 | B12: 11 | C12: Charles | D12: Nelson | E12: charles.nelson11@example.com | F12: 1589.9 | G12: Emergency Relief | H12: Online | I12: GivingTuesday | J12: 2025-11-09 | K12: Yes
A13: 11 | B13: 11 | C13: Charles | D13: Nelson | E13: charles.nelson11@example.com | F13: 477.14 | G13: Food Bank | H13: Online | I13: Year-End Appeal | J13: 2025-02-17 | K13: Yes
A14: 12 | B14: 11 | C14: Charles | D14: Nelson | E14: charles.nelson11@example.com | F14: 291.76 | G14: Youth Programs | H14: Credit card | I14: Spring Drive | J14: 2025-09-09 | K14: Yes
A15: 13 | B15: 11 | C15: Charles | D15: Nelson | E15: charles.nelson11@example.com | F15: 131.67 | G15: Food Bank | H15: Online | I15: GivingTuesday | J15: 2025-01-12 | K15: Yes
A16: 14 | B16: 13 | C16: Dorothy | D16: Allen | E16: dorothy.allen13@example.com | F16: 48.09 | G16: Emergency Relief | H16: Online | I16: Fall Campaign | J16: 2026-02-19 | K16: Yes
A17: 15 | B17: 13 | C17: Dorothy | D17: Allen | E17: dorothy.allen13@example.com | F17: 1395.72 | G17: General Fund | H17: Online | I17: Year-End Appeal | J17: 2025-02-04 | K17: Yes
A18: 16 | B18: 13 | C18: Dorothy | D18: Allen | E18: dorothy.allen13@example.com | F18: 84.02 | G18: Youth Programs | H18: Online | J18: 2025-08-27 | K18: Yes
A19: 17 | B19: 14 | C19: Emily | D19: Baker | E19: emily.baker14@example.com | F19: 85.98 | G19: Youth Programs | H19: Credit card | I19: Fall Campaign | J19: 2025-11-09 | K19: Yes
A20: 18 | B20: 14 | C20: Emily | D20: Baker | E20: emily.baker14@example.com | F20: 22.9 | G20: Youth Programs | H20: Check | J20: 2025-02-27 | K20: Yes
A21: 19 | B21: 15 | C21: Elizabeth | D21: Green | E21: elizabeth.green15@example.com | F21: 37.29 | G21: General Fund | H21: Check | I21: Spring Drive | J21: 2026-02-23 | K21: Yes
A22: 20 | B22: 15 | C22: Elizabeth | D22: Green | E22: elizabeth.green15@example.com | F22: 69.16 | G22: General Fund | H22: Check | I22: Year-End Appeal | J22: 2025-06-29 | K22: Yes
A23: 21 | B23: 15 | C23: Elizabeth | D23: Green | E23: elizabeth.green15@example.com | F23: 80.63 | G23: Endowment | H23: Online | I23: Spring Drive | J23: 2025-12-03 | K23: Yes
A24: 22 | B24: 17 | C24: Emily | D24: Santos | E24: emily.santos17@example.com | F24: 126.99 | G24: General Fund | H24: Cash | J24: 2025-12-15 | K24: Yes
A25: 23 | B25: 17 | C25: Emily | D25: Santos | E25: emily.santos17@example.com | F25: 282.52 | G25: Endowment | H25: Credit card | I25: GivingTuesday | J25: 2025-09-07 | K25: Yes
A26: 24 | B26: 17 | C26: Emily | D26: Santos | E26: emily.santos17@example.com | F26: 14.78 | G26: Emergency Relief | H26: Cash | I26: GivingTuesday | J26: 2025-02-03 | K26: Yes
A27: 25 | B27: 17 | C27: Emily | D27: Santos | E27: emily.santos17@example.com | F27: 30.89 | G27: Emergency Relief | H27: Online | I27: Spring Drive | J27: 2025-01-12 | K27: Yes
A28: 26 | B28: 18 | C28: William | D28: Martinez | E28: william.martinez18@example.com | F28: 29.93 | G28: Food Bank | H28: Credit card | I28: GivingTuesday | J28: 2025-11-04 | K28: Yes
A29: 27 | B29: 18 | C29: William | D29: Martinez | E29: william.martinez18@example.com | F29: 471.17 | G29: Endowment | H29: Cash | I29: Spring Drive | J29: 2025-02-27 | K29: Yes
A30: 28 | B30: 18 | C30: William | D30: Martinez | E30: william.martinez18@example.com | F30: 44.48 | G30: Endowment | H30: Check | I30: GivingTuesday | J30: 2025-01-04 | K30: Yes
A31: 29 | B31: 21 | C31: William | D31: Walker | E31: william.walker21@example.com | F31: 252.1 | G31: Emergency Relief | H31: Cash | I31: GivingTuesday | J31: 2026-02-09 | K31: Yes
A32: 30 | B32: 21 | C32: William | D32: Walker | E32: william.walker21@example.com | F32: 24.22 | G32: Food Bank | H32: Credit card | I32: Year-End Appeal | J32: 2024-12-21 | K32: Yes
A33: 31 | B33: 21 | C33: William | D33: Walker | E33: william.walker21@example.com | F33: 1884.48 | G33: General Fund | H33: Online | I33: Spring Drive | J33: 2025-10-12 | K33: Yes
A34: 32 | B34: 21 | C34: William | D34: Walker | E34: william.walker21@example.com | F34: 161.21 | G34: Food Bank | H34: Check | J34: 2025-11-12 | K34: Yes
A35: 33 | B35: 27 | C35: Thomas | D35: Garcia | E35: thomas.garcia27@example.com | F35: 671.26 | G35: General Fund | H35: Cash | I35: Year-End Appeal | J35: 2025-11-09 | K35: Yes
A36: 34 | B36: 28 | C36: Steven | D36: Harris | E36: steven.harris28@example.com | F36: 140.06 | G36: Food Bank | H36: Online | J36: 2026-03-26 | K36: Yes
A37: 35 | B37: 28 | C37: Steven | D37: Harris | E37: steven.harris28@example.com | F37: 36.6 | G37: Emergency Relief | H37: Check | I37: Spring Drive | J37: 2025-04-14 | K37: Yes
A38: 36 | B38: 28 | C38: Steven | D38: Harris | E38: steven.harris28@example.com | F38: 525.67 | G38: Food Bank | H38: Check | I38: GivingTuesday | J38: 2025-07-03 | K38: Yes
A39: 37 | B39: 28 | C39: Steven | D39: Harris | E39: steven.harris28@example.com | F39: 710.18 | G39: Endowment | H39: Online | J39: 2025-03-17 | K39: Yes
A40: 38 | B40: 29 | C40: Sandra | D40: Lewis | E40: sandra.lewis29@example.com | F40: 45.5 | G40: Food Bank | H40: Credit card | I40: Year-End Appeal | J40: 2026-04-01 | K40: Yes
...

Sheet Lapsed Outreach
A1: Lapsed Donor Outreach — Auto-updates when donors haven't given in 90+ days
A2: SETTINGS: Change the thresholds in row 4 (yellow cells) to adjust who appears on this list.
B4: Days since last gift ≥ | E4: 90 | F4: Donors who haven't given in this many days | G4: Min. lifetime giving ≥ | J4: 0 | K4: Set to e.g. 50 to exclude small donors
A6: # | B6: Contact ID | C6: First name | D6: Last name | E6: Email | F6: Phone | G6: Last gift date | H6: Days since gift | I6: Total given | J6: Tier | K6: Suggested action | L6: Outreach notes
A7: 1 | B7: 30 | C7: Daniel | D7: Nguyen | E7: daniel.nguyen30@example.com | F7: 555-1029 | G7: 2026-01-02 | H7: 96 | I7: 461.65 | J7: Sustainer | K7: Send personal thank-you + update
A8: 2 | B8: 40 | C8: Lisa | D8: Harris | E8: lisa.harris40@example.com | F8: 555-1039 | G8: 2025-12-20 | H8: 109 | I8: 1383.45 | J8: Champion | K8: Send personal thank-you + update
A9: 3 | B9: 17 | C9: Emily | D9: Santos | E9: emily.santos17@example.com | F9: 555-1016 | G9: 2025-12-15 | H9: 114 | I9: 455.18 | J9: Sustainer | K9: Send personal thank-you + update
A10: 4 | B10: 35 | C10: Emily | D10: Scott | E10: emily.scott35@example.com | F10: 555-1034 | G10: 2025-12-02 | H10: 127 | I10: 1145.98 | J10: Champion | K10: Send personal thank-you + update
A11: 5 | B11: 36 | C11: Andrew | D11: Kim | E11: andrew.kim36@example.com | F11: 555-1035 | G11: 2025-12-01 | H11: 128 | I11: 903.88 | J11: Champion | K11: Send personal thank-you + update
A12: 6 | B12: 1 | C12: William | D12: Thornton | E12: william.thornton1@example.com | F12: 555-1000 | G12: 2025-11-21 | H12: 138 | I12: 291.61 | J12: Sustainer | K12: Send personal thank-you + update
A13: 7 | B13: 11 | C13: Charles | D13: Nelson | E13: charles.nelson11@example.com | F13: 555-1010 | G13: 2025-11-09 | H13: 150 | I13: 2490.47 | J13: Major | K13: Send personal thank-you + update
A14: 8 | B14: 14 | C14: Emily | D14: Baker | E14: emily.baker14@example.com | F14: 555-1013 | G14: 2025-11-09 | H14: 150 | I14: 108.88 | J14: Sustainer | K14: Send personal thank-you + update
A15: 9 | B15: 27 | C15: Thomas | D15: Garcia | E15: thomas.garcia27@example.com | F15: 555-1026 | G15: 2025-11-09 | H15: 150 | I15: 671.26 | J15: Champion | K15: Send personal thank-you + update
A16: 10 | B16: 18 | C16: William | D16: Martinez | E16: william.martinez18@example.com | F16: 555-1017 | G16: 2025-11-04 | H16: 155 | I16: 545.58 | J16: Champion | K16: Send personal thank-you + update
A17: 11 | B17: 34 | C17: Maria | D17: Hall | E17: maria.hall34@example.com | F17: 555-1033 | G17: 2025-03-22 | H17: 382 | I17: 373.4 | J17: Sustainer | K17: Reactivation email + special ask
A18: 12 | B18: 33 | C18: Dorothy | D18: Hill | E18: dorothy.hill33@example.com | F18: 555-1032 | G18: 2024-10-28 | H18: 527 | I18: 1725.06 | J18: Champion | K18: Reactivation email + special ask
A20: Total lapsed donors | C20: 12 | E20: Est. recoverable giving | G20: =SUM(I7:I18) | I20: Avg days since last gift | K20: =IFERROR(AVERAGE(H7:H18),0)
A22: Outreach urgency legend: | C22: 90–180 days | E22: 181–365 days | G22: 365+ days

Sheet Contacts
A1: Contacts — Master list of all people in your CRM
A2: ID | B2: First name | C2: Last name | D2: Email | E2: Phone | F2: City | G2: Type | H2: Status | I2: Score | J2: Source
A3: 1 | B3: William | C3: Thornton | D3: william.thornton1@example.com | E3: 555-1000 | F3: Riverside | G3: Donor | H3: Active | I3: 43 | J3: Event
A4: 2 | B4: Andrew | C4: Ortiz | D4: andrew.ortiz2@example.com | E4: 555-1001 | F4: Springfield | G4: Volunteer | H4: Active | I4: 18 | J4: Referral
A5: 3 | B5: Paul | C5: Perez | D5: paul.perez3@example.com | E5: 555-1002 | F5: Maplewood | G5: Volunteer | H5: Active | I5: 84 | J5: Referral
A6: 4 | B6: Donna | C6: Garcia | D6: donna.garcia4@example.com | E6: 555-1003 | F6: Maplewood | G6: Volunteer | H6: Active | I6: 35 | J6: Online signup
A7: 5 | B7: David | C7: Jackson | D7: david.jackson5@example.com | E7: 555-1004 | F7: Springfield | G7: Both | H7: Active | I7: 63 | J7: Referral
A8: 6 | B8: George | C8: Martin | D8: george.martin6@example.com | E8: 555-1005 | F8: Springfield | G8: Volunteer | H8: Active | I8: 83 | J8: Event
A9: 7 | B9: Emily | C9: Martinez | D9: emily.martinez7@example.com | E9: 555-1006 | F9: Riverside | G9: Donor | H9: Active | I9: 61 | J9: Referral
A10: 8 | B10: Jessica | C10: Martinez | D10: jessica.martinez8@example.com | E10: 555-1007 | F10: Springfield | G10: Volunteer | H10: Lapsed | I10: 27 | J10: Referral
A11: 9 | B11: Ashley | C11: Walker | D11: ashley.walker9@example.com | E11: 555-1008 | F11: Oakdale | G11: Donor | H11: Active | I11: 41 | J11: Referral
A12: 10 | B12: Linda | C12: Perez | D12: linda.perez10@example.com | E12: 555-1009 | F12: Riverside | G12: Donor | H12: Active | I12: 46 | J12: Online signup
A13: 11 | B13: Charles | C13: Nelson | D13: charles.nelson11@example.com | E13: 555-1010 | F13: Riverside | G13: Donor | H13: Active | I13: 22 | J13: Referral
A14: 12 | B14: Anthony | C14: Garcia | D14: anthony.garcia12@example.com | E14: 555-1011 | F14: Oakdale | G14: Volunteer | H14: Active | I14: 87 | J14: Walk-in
... A42: 40 | B42: Lisa | C42: Harris | D42: lisa.harris40@example.com | E42: 555-1039 | F42: Maplewood | G42: Both | H42: Active | I42: 53 | J42: Referral
